Workbook

Sheet README
A1: Andah KTDI model, seed-driven
A3: THE SEED
A4: Config!B2. Change it to any whole number and every random element re-rolls across all 172
A5: countries at once. The same seed always rebuilds the same world, so nothing is lost by trying one.
A6: Config!B3 is the dice strength; set it to 0 to switch the randomness off completely and keep only
A7: the real analogue data.
A8: Moving from seed 1765 to 4242 changes 157 of the 172 KTDI values, by a median of 0.013 and at
A9: most 0.143.
A11: WHY THERE IS A HOME-MADE RANDOM GENERATOR IN HERE
A12: Excel has no seeded random function. RAND() cannot be reproduced and recalculates on every edit,
A13: which would mean the file never showed the same world twice. So the dice are a linear congruential
A14: generator over the seed and a fixed per-country Dice ID, in the hidden u1/u2/u3 columns. It is
... A43: Earth analogues into the Earth Comparsion sheet is the fix; raising the dice barely moves it.

Sheet KTDI Model
A1: Country | B1: Continent | C1: Archetypes | D1: GDP per capita, nominal (lahn) | E1: GDP per capita, nominal (US$) | F1: log income | G1: Income index | H1: u1 | I1: u2 | J1: u3 | K1: own dev h | L1: own dev e | M1: sib count | N1: sib pick | O1: dev h used | P1: dev e used | Q1: exp health | R1: exp educ | S1: health idx raw | T1: Life expectancy (auto) | U1: Life expectancy (yours) | V1: Life expectancy (used) | W1: educ idx target | X1: eys0 | Y1: mys0 | Z1: ie0 | AA1: Expected yrs schooling (auto) | AB1: (yours) | AC1: (used) | AD1: Mean yrs schooling (auto) | AE1: (yours) | AF1: (used) | AG1: Health index | AH1: Education index | AI1: KTDI computed | AJ1: KTDI published | AK1: Change | AL1: Change vs shared shift | AM1: Review | AN1: Rank computed | AO1: Rank published | AP1: Dice ID (do not edit or sort away)
A2: Acetoa | B2: Acrola | C2: — | D2: 66667 | E2: =D2*Config!$B$4 | F2: =LN(MAX(60,E2)) | G2: =MEDIAN(0,(F2-LN(Config!$B$5))/(LN(Config!$B$6)-LN(Config!$B$5)),1) | H2: =MOD((Config!$B$2+$AP2*7919)*9301+49297,233280)/233280 | I2: =MOD((Config!$B$2+$AP2*104729)*4096+150889,714025)/714025 | J2: =MOD((Config!$B$2*31+$AP2*15485863)*1366+150889,714025)/714025 | M2: =COUNTIF(Siblings!$A$2:$A$84,B2) | N2: =1+INT(J2*M2) | O2: =IF(K2<>"",K2,IFERROR(INDEX(Siblings!$D$2:$D$84,MATCH(B2&"|"&N2,Siblings!$F$2:$F$84,0)),0)) | P2: =IF(L2<>"",L2,IFERROR(INDEX(Siblings!$E$2:$E$84,MATCH(B2&"|"&N2,Siblings!$F$2:$F$84,0)),0)) | Q2: =(INDEX('Earth curves'!$B$2:$B$46,MAX(1,MIN(44,IFERROR(MATCH(F2,'Earth curves'!$A$2:$A$46,1),1))))+(F2-INDEX('Earth curves'!$A$2:$A$46,MAX(1,MIN(44,IFERROR(MATCH(F2,'Earth curves'!$A$2:$A$46,1),1)))))*(INDEX('Earth curves'!$B$2:$B$46,MAX(1,MIN(44,IFERROR(MATCH(F2,'Earth curves'!$A$2:$A$46,1),1)))+1)-INDEX('Earth curves'!$B$2:$B$46,MAX(1,MIN(44,IFERROR(MATCH(F2,'Earth curves'!$A$2:$A$46,1),1)))))/(INDEX('Earth curves'!$A$2:$A$46,MAX(1,MIN(44,IFERROR(MATCH(F2,'Earth curves'!$A$2:$A$46,1),1)))+1)-INDEX('Earth curves'!$A$2:$A$46,MAX(1,MIN(44,IFERROR(MATCH(F2,'Earth curves'!$A$2:$A$46,1),1)))))) | R2: =(INDEX('Earth curves'!$C$2:$C$46,MAX(1,MIN(44,IFERROR(MATCH(F2,'Earth curves'!$A$2:$A$46,1),1))))+(F2-INDEX('Earth curves'!$A$2:$A$46,MAX(1,MIN(44,IFERROR(MATCH(F2,'Earth curves'!$A$2:$A$46,1),1)))))*(INDEX('Earth curves'!$C$2:$C$46,MAX(1,MIN(44,IFERROR(MATCH(F2,'Earth curves'!$A$2:$A$46,1),1)))+1)-INDEX('Earth curves'!$C$2:$C$46,MAX(1,MIN(44,IFERROR(MATCH(F2,'Earth curves'!$A$2:$A$46,1),1)))))/(INDEX('Earth curves'!$A$2:$A$46,MAX(1,MIN(44,IFERROR(MATCH(F2,'Earth curves'!$A$2:$A$46,1),1)))+1)-INDEX('Earth curves'!$A$2:$A$46,MAX(1,MIN(44,IFERROR(MATCH(F2,'Earth curves'!$A$2:$A$46,1),1)))))) | S2: =MEDIAN(0.307692,Q2+MEDIAN(-0.350583,O2+NORMSINV(H2)*0.064828*Config!$B$3,0.120277),0.993846) | T2: =ROUND(Config!$B$7+(Config!$B$8-Config!$B$7)*S2,1) | V2: =IF(U2="",T2,U2) | W2: =MEDIAN(0.05,R2+MEDIAN(-0.302219,P2+NORMSINV(I2)*0.089531*Config!$B$3,0.274961),0.999) | X2: =(INDEX('Earth curves'!$F$2:$F$46,MAX(1,MIN(44,IFERROR(MATCH(W2,'Earth curves'!$E$2:$E$46,1),1))))+(W2-INDEX('Earth curves'!$E$2:$E$46,MAX(1,MIN(44,IFERROR(MATCH(W2,'Earth curves'!$E$2:$E$46,1),1)))))*(INDEX('Earth curves'!$F$2:$F$46,MAX(1,MIN(44,IFERROR(MATCH(W2,'Earth curves'!$E$2:$E$46,1),1)))+1)-INDEX('Earth curves'!$F$2:$F$46,MAX(1,MIN(44,IFERROR(MATCH(W2,'Earth curves'!$E$2:$E$46,1),1)))))/(INDEX('Earth curves'!$E$2:$E$46,MAX(1,MIN(44,IFERROR(MATCH(W2,'Earth curves'!$E$2:$E$46,1),1)))+1)-INDEX('Earth curves'!$E$2:$E$46,MAX(1,MIN(44,IFERROR(MATCH(W2,'Earth curves'!$E$2:$E$46,1),1)))))) | Y2: =(INDEX('Earth curves'!$G$2:$G$46,MAX(1,MIN(44,IFERROR(MATCH(W2,'Earth curves'!$E$2:$E$46,1),1))))+(W2-INDEX('Earth curves'!$E$2:$E$46,MAX(1,MIN(44,IFERROR(MATCH(W2,'Earth curves'!$E$2:$E$46,1),1)))))*(INDEX('Earth curves'!$G$2:$G$46,MAX(1,MIN(44,IFERROR(MATCH(W2,'Earth curves'!$E$2:$E$46,1),1)))+1)-INDEX('Earth curves'!$G$2:$G$46,MAX(1,MIN(44,IFERROR(MATCH(W2,'Earth curves'!$E$2:$E$46,1),1)))))/(INDEX('Earth curves'!$E$2:$E$46,MAX(1,MIN(44,IFERROR(MATCH(W2,'Earth curves'!$E$2:$E$46,1),1)))+1)-INDEX('Earth curves'!$E$2:$E$46,MAX(1,MIN(44,IFERROR(MATCH(W2,'Earth curves'!$E$2:$E$46,1),1)))))) | Z2: =(MIN(X2/Config!$B$9,1)+MIN(Y2/Config!$B$10,1))/2 | AA2: =ROUND(MIN(22,MAX(3,X2*W2/Z2)),1) | AC2: =IF(AB2="",AA2,AB2) | AD2: =ROUND(MIN(Config!$B$10,MAX(1,Y2*W2/Z2)),1) | AF2: =IF(AE2="",AD2,AE2) | AG2: =(V2-Config!$B$7)/(Config!$B$8-Config!$B$7) | AH2: =(MIN(AC2/Config!$B$9,1)+MIN(AF2/Config!$B$10,1))/2 | AI2: =ROUND((AG2*AH2*G2)^(1/3),3) | AJ2: 0.779 | AK2: =AI2-AJ2 | AL2: =AK2-AVERAGE($AK$2:$AK$173) | AM2: =IF(ABS(AL2)>Config!$B$11,"REVIEW","") | AN2: =RANK(AI2,$AI$2:$AI$173) | AO2: =RANK(AJ2,$AJ$2:$AJ$173) | AP2: 2
A3: Acrana | B3: Ayuma | C3: militarised, resource | D3: 70794 | E3: =D3*Config!$B$4 | F3: =LN(MAX(60,E3)) | G3: =MEDIAN(0,(F3-LN(Config!$B$5))/(LN(Config!$B$6)-LN(Config!$B$5)),1) | H3: =MOD((Config!$B$2+$AP3*7919)*9301+49297,233280)/233280 | I3: =MOD((Config!$B$2+$AP3*104729)*4096+150889,714025)/714025 | J3: =MOD((Config!$B$2*31+$AP3*15485863)*1366+150889,714025)/714025 | K3: 0.036007 | L3: 0.071534 | M3: =COUNTIF(Siblings!$A$2:$A$84,B3) | N3: =1+INT(J3*M3) | O3: =IF(K3<>"",K3,IFERROR(INDEX(Siblings!$D$2:$D$84,MATCH(B3&"|"&N3,Siblings!$F$2:$F$84,0)),0)) | P3: =IF(L3<>"",L3,IFERROR(INDEX(Siblings!$E$2:$E$84,MATCH(B3&"|"&N3,Siblings!$F$2:$F$84,0)),0)) | Q3: =(INDEX('Earth curves'!$B$2:$B$46,MAX(1,MIN(44,IFERROR(MATCH(F3,'Earth curves'!$A$2:$A$46,1),1))))+(F3-INDEX('Earth curves'!$A$2:$A$46,MAX(1,MIN(44,IFERROR(MATCH(F3,'Earth curves'!$A$2:$A$46,1),1)))))*(INDEX('Earth curves'!$B$2:$B$46,MAX(1,MIN(44,IFERROR(MATCH(F3,'Earth curves'!$A$2:$A$46,1),1)))+1)-INDEX('Earth curves'!$B$2:$B$46,MAX(1,MIN(44,IFERROR(MATCH(F3,'Earth curves'!$A$2:$A$46,1),1)))))/(INDEX('Earth curves'!$A$2:$A$46,MAX(1,MIN(44,IFERROR(MATCH(F3,'Earth curves'!$A$2:$A$46,1),1)))+1)-INDEX('Earth curves'!$A$2:$A$46,MAX(1,MIN(44,IFERROR(MATCH(F3,'Earth curves'!$A$2:$A$46,1),1)))))) | R3: =(INDEX('Earth curves'!$C$2:$C$46,MAX(1,MIN(44,IFERROR(MATCH(F3,'Earth curves'!$A$2:$A$46,1),1))))+(F3-INDEX('Earth curves'!$A$2:$A$46,MAX(1,MIN(44,IFERROR(MATCH(F3,'Earth curves'!$A$2:$A$46,1),1)))))*(INDEX('Earth curves'!$C$2:$C$46,MAX(1,MIN(44,IFERROR(MATCH(F3,'Earth curves'!$A$2:$A$46,1),1)))+1)-INDEX('Earth curves'!$C$2:$C$46,MAX(1,MIN(44,IFERROR(MATCH(F3,'Earth curves'!$A$2:$A$46,1),1)))))/(INDEX('Earth curves'!$A$2:$A$46,MAX(1,MIN(44,IFERROR(MATCH(F3,'Earth curves'!$A$2:$A$46,1),1)))+1)-INDEX('Earth curves'!$A$2:$A$46,MAX(1,MIN(44,IFERROR(MATCH(F3,'Earth curves'!$A$2:$A$46,1),1)))))) | S3: =MEDIAN(0.307692,Q3+MEDIAN(-0.350583,O3+NORMSINV(H3)*0.064828*Config!$B$3,0.120277),0.993846) | T3: =ROUND(Config!$B$7+(Config!$B$8-Config!$B$7)*S3,1) | V3: =IF(U3="",T3,U3) | W3: =MEDIAN(0.05,R3+MEDIAN(-0.302219,P3+NORMSINV(I3)*0.089531*Config!$B$3,0.274961),0.999) | X3: =(INDEX('Earth curves'!$F$2:$F$46,MAX(1,MIN(44,IFERROR(MATCH(W3,'Earth curves'!$E$2:$E$46,1),1))))+(W3-INDEX('Earth curves'!$E$2:$E$46,MAX(1,MIN(44,IFERROR(MATCH(W3,'Earth curves'!$E$2:$E$46,1),1)))))*(INDEX('Earth curves'!$F$2:$F$46,MAX(1,MIN(44,IFERROR(MATCH(W3,'Earth curves'!$E$2:$E$46,1),1)))+1)-INDEX('Earth curves'!$F$2:$F$46,MAX(1,MIN(44,IFERROR(MATCH(W3,'Earth curves'!$E$2:$E$46,1),1)))))/(INDEX('Earth curves'!$E$2:$E$46,MAX(1,MIN(44,IFERROR(MATCH(W3,'Earth curves'!$E$2:$E$46,1),1)))+1)-INDEX('Earth curves'!$E$2:$E$46,MAX(1,MIN(44,IFERROR(MATCH(W3,'Earth curves'!$E$2:$E$46,1),1)))))) | Y3: =(INDEX('Earth curves'!$G$2:$G$46,MAX(1,MIN(44,IFERROR(MATCH(W3,'Earth curves'!$E$2:$E$46,1),1))))+(W3-INDEX('Earth curves'!$E$2:$E$46,MAX(1,MIN(44,IFERROR(MATCH(W3,'Earth curves'!$E$2:$E$46,1),1)))))*(INDEX('Earth curves'!$G$2:$G$46,MAX(1,MIN(44,IFERROR(MATCH(W3,'Earth curves'!$E$2:$E$46,1),1)))+1)-INDEX('Earth curves'!$G$2:$G$46,MAX(1,MIN(44,IFERROR(MATCH(W3,'Earth curves'!$E$2:$E$46,1),1)))))/(INDEX('Earth curves'!$E$2:$E$46,MAX(1,MIN(44,IFERROR(MATCH(W3,'Earth curves'!$E$2:$E$46,1),1)))+1)-INDEX('Earth curves'!$E$2:$E$46,MAX(1,MIN(44,IFERROR(MATCH(W3,'Earth curves'!$E$2:$E$46,1),1)))))) | Z3: =(MIN(X3/Config!$B$9,1)+MIN(Y3/Config!$B$10,1))/2 | AA3: =ROUND(MIN(22,MAX(3,X3*W3/Z3)),1) | AC3: =IF(AB3="",AA3,AB3) | AD3: =ROUND(MIN(Config!$B$10,MAX(1,Y3*W3/Z3)),1) | AF3: =IF(AE3="",AD3,AE3) | AG3: =(V3-Config!$B$7)/(Config!$B$8-Config!$B$7) | AH3: =(MIN(AC3/Config!$B$9,1)+MIN(AF3/Config!$B$10,1))/2 | AI3: =ROUND((AG3*AH3*G3)^(1/3),3) | AJ3: 0.89 | AK3: =AI3-AJ3 | AL3: =AK3-AVERAGE($AK$2:$AK$173) | AM3: =IF(ABS(AL3)>Config!$B$11,"REVIEW","") | AN3: =RANK(AI3,$AI$2:$AI$173) | AO3: =RANK(AJ3,$AJ$2:$AJ$173) | AP3: 3
A4: Aetintio | B4: Atirha | C4: — | D4: 58095 | E4: =D4*Config!$B$4 | F4: =LN(MAX(60,E4)) | G4: =MEDIAN(0,(F4-LN(Config!$B$5))/(LN(Config!$B$6)-LN(Config!$B$5)),1) | H4: =MOD((Config!$B$2+$AP4*7919)*9301+49297,233280)/233280 | I4: =MOD((Config!$B$2+$AP4*104729)*4096+150889,714025)/714025 | J4: =MOD((Config!$B$2*31+$AP4*15485863)*1366+150889,714025)/714025 | M4: =COUNTIF(Siblings!$A$2:$A$84,B4) | N4: =1+INT(J4*M4) | O4: =IF(K4<>"",K4,IFERROR(INDEX(Siblings!$D$2:$D$84,MATCH(B4&"|"&N4,Siblings!$F$2:$F$84,0)),0)) | P4: =IF(L4<>"",L4,IFERROR(INDEX(Siblings!$E$2:$E$84,MATCH(B4&"|"&N4,Siblings!$F$2:$F$84,0)),0)) | Q4: =(INDEX('Earth curves'!$B$2:$B$46,MAX(1,MIN(44,IFERROR(MATCH(F4,'Earth curves'!$A$2:$A$46,1),1))))+(F4-INDEX('Earth curves'!$A$2:$A$46,MAX(1,MIN(44,IFERROR(MATCH(F4,'Earth curves'!$A$2:$A$46,1),1)))))*(INDEX('Earth curves'!$B$2:$B$46,MAX(1,MIN(44,IFERROR(MATCH(F4,'Earth curves'!$A$2:$A$46,1),1)))+1)-INDEX('Earth curves'!$B$2:$B$46,MAX(1,MIN(44,IFERROR(MATCH(F4,'Earth curves'!$A$2:$A$46,1),1)))))/(INDEX('Earth curves'!$A$2:$A$46,MAX(1,MIN(44,IFERROR(MATCH(F4,'Earth curves'!$A$2:$A$46,1),1)))+1)-INDEX('Earth curves'!$A$2:$A$46,MAX(1,MIN(44,IFERROR(MATCH(F4,'Earth curves'!$A$2:$A$46,1),1)))))) | R4: =(INDEX('Earth curves'!$C$2:$C$46,MAX(1,MIN(44,IFERROR(MATCH(F4,'Earth curves'!$A$2:$A$46,1),1))))+(F4-INDEX('Earth curves'!$A$2:$A$46,MAX(1,MIN(44,IFERROR(MATCH(F4,'Earth curves'!$A$2:$A$46,1),1)))))*(INDEX('Earth curves'!$C$2:$C$46,MAX(1,MIN(44,IFERROR(MATCH(F4,'Earth curves'!$A$2:$A$46,1),1)))+1)-INDEX('Earth curves'!$C$2:$C$46,MAX(1,MIN(44,IFERROR(MATCH(F4,'Earth curves'!$A$2:$A$46,1),1)))))/(INDEX('Earth curves'!$A$2:$A$46,MAX(1,MIN(44,IFERROR(MATCH(F4,'Earth curves'!$A$2:$A$46,1),1)))+1)-INDEX('Earth curves'!$A$2:$A$46,MAX(1,MIN(44,IFERROR(MATCH(F4,'Earth curves'!$A$2:$A$46,1),1)))))) | S4: =MEDIAN(0.307692,Q4+MEDIAN(-0.350583,O4+NORMSINV(H4)*0.064828*Config!$B$3,0.120277),0.993846) | T4: =ROUND(Config!$B$7+(Config!$B$8-Config!$B$7)*S4,1) | V4: =IF(U4="",T4,U4) | W4: =MEDIAN(0.05,R4+MEDIAN(-0.302219,P4+NORMSINV(I4)*0.089531*Config!$B$3,0.274961),0.999) | X4: =(INDEX('Earth curves'!$F$2:$F$46,MAX(1,MIN(44,IFERROR(MATCH(W4,'Earth curves'!$E$2:$E$46,1),1))))+(W4-INDEX('Earth curves'!$E$2:$E$46,MAX(1,MIN(44,IFERROR(MATCH(W4,'Earth curves'!$E$2:$E$46,1),1)))))*(INDEX('Earth curves'!$F$2:$F$46,MAX(1,MIN(44,IFERROR(MATCH(W4,'Earth curves'!$E$2:$E$46,1),1)))+1)-INDEX('Earth curves'!$F$2:$F$46,MAX(1,MIN(44,IFERROR(MATCH(W4,'Earth curves'!$E$2:$E$46,1),1)))))/(INDEX('Earth curves'!$E$2:$E$46,MAX(1,MIN(44,IFERROR(MATCH(W4,'Earth curves'!$E$2:$E$46,1),1)))+1)-INDEX('Earth curves'!$E$2:$E$46,MAX(1,MIN(44,IFERROR(MATCH(W4,'Earth curves'!$E$2:$E$46,1),1)))))) | Y4: =(INDEX('Earth curves'!$G$2:$G$46,MAX(1,MIN(44,IFERROR(MATCH(W4,'Earth curves'!$E$2:$E$46,1),1))))+(W4-INDEX('Earth curves'!$E$2:$E$46,MAX(1,MIN(44,IFERROR(MATCH(W4,'Earth curves'!$E$2:$E$46,1),1)))))*(INDEX('Earth curves'!$G$2:$G$46,MAX(1,MIN(44,IFERROR(MATCH(W4,'Earth curves'!$E$2:$E$46,1),1)))+1)-INDEX('Earth curves'!$G$2:$G$46,MAX(1,MIN(44,IFERROR(MATCH(W4,'Earth curves'!$E$2:$E$46,1),1)))))/(INDEX('Earth curves'!$E$2:$E$46,MAX(1,MIN(44,IFERROR(MATCH(W4,'Earth curves'!$E$2:$E$46,1),1)))+1)-INDEX('Earth curves'!$E$2:$E$46,MAX(1,MIN(44,IFERROR(MATCH(W4,'Earth curves'!$E$2:$E$46,1),1)))))) | Z4: =(MIN(X4/Config!$B$9,1)+MIN(Y4/Config!$B$10,1))/2 | AA4: =ROUND(MIN(22,MAX(3,X4*W4/Z4)),1) | AC4: =IF(AB4="",AA4,AB4) | AD4: =ROUND(MIN(Config!$B$10,MAX(1,Y4*W4/Z4)),1) | AF4: =IF(AE4="",AD4,AE4) | AG4: =(V4-Config!$B$7)/(Config!$B$8-Config!$B$7) | AH4: =(MIN(AC4/Config!$B$9,1)+MIN(AF4/Config!$B$10,1))/2 | AI4: =ROUND((AG4*AH4*G4)^(1/3),3) | AJ4: 0.815 | AK4: =AI4-AJ4 | AL4: =AK4-AVERAGE($AK$2:$AK$173) | AM4: =IF(ABS(AL4)>Config!$B$11,"REVIEW","") | AN4: =RANK(AI4,$AI$2:$AI$173) | AO4: =RANK(AJ4,$AJ$2:$AJ$173) | AP4: 4
A5: Ahokini | B5: Quia | C5: petro | D5: 185397 | E5: =D5*Config!$B$4 | F5: =LN(MAX(60,E5)) | G5: =MEDIAN(0,(F5-LN(Config!$B$5))/(LN(Config!$B$6)-LN(Config!$B$5)),1) | H5: =MOD((Config!$B$2+$AP5*7919)*9301+49297,233280)/233280 | I5: =MOD((Config!$B$2+$AP5*104729)*4096+150889,714025)/714025 | J5: =MOD((Config!$B$2*31+$AP5*15485863)*1366+150889,714025)/714025 | K5: 0.048663 | L5: 0.038869 | M5: =COUNTIF(Siblings!$A$2:$A$84,B5) | N5: =1+INT(J5*M5) | O5: =IF(K5<>"",K5,IFERROR(INDEX(Siblings!$D$2:$D$84,MATCH(B5&"|"&N5,Siblings!$F$2:$F$84,0)),0)) | P5: =IF(L5<>"",L5,IFERROR(INDEX(Siblings!$E$2:$E$84,MATCH(B5&"|"&N5,Siblings!$F$2:$F$84,0)),0)) | Q5: =(INDEX('Earth curves'!$B$2:$B$46,MAX(1,MIN(44,IFERROR(MATCH(F5,'Earth curves'!$A$2:$A$46,1),1))))+(F5-INDEX('Earth curves'!$A$2:$A$46,MAX(1,MIN(44,IFERROR(MATCH(F5,'Earth curves'!$A$2:$A$46,1),1)))))*(INDEX('Earth curves'!$B$2:$B$46,MAX(1,MIN(44,IFERROR(MATCH(F5,'Earth curves'!$A$2:$A$46,1),1)))+1)-INDEX('Earth curves'!$B$2:$B$46,MAX(1,MIN(44,IFERROR(MATCH(F5,'Earth curves'!$A$2:$A$46,1),1)))))/(INDEX('Earth curves'!$A$2:$A$46,MAX(1,MIN(44,IFERROR(MATCH(F5,'Earth curves'!$A$2:$A$46,1),1)))+1)-INDEX('Earth curves'!$A$2:$A$46,MAX(1,MIN(44,IFERROR(MATCH(F5,'Earth curves'!$A$2:$A$46,1),1)))))) | R5: =(INDEX('Earth curves'!$C$2:$C$46,MAX(1,MIN(44,IFERROR(MATCH(F5,'Earth curves'!$A$2:$A$46,1),1))))+(F5-INDEX('Earth curves'!$A$2:$A$46,MAX(1,MIN(44,IFERROR(MATCH(F5,'Earth curves'!$A$2:$A$46,1),1)))))*(INDEX('Earth curves'!$C$2:$C$46,MAX(1,MIN(44,IFERROR(MATCH(F5,'Earth curves'!$A$2:$A$46,1),1)))+1)-INDEX('Earth curves'!$C$2:$C$46,MAX(1,MIN(44,IFERROR(MATCH(F5,'Earth curves'!$A$2:$A$46,1),1)))))/(INDEX('Earth curves'!$A$2:$A$46,MAX(1,MIN(44,IFERROR(MATCH(F5,'Earth curves'!$A$2:$A$46,1),1)))+1)-INDEX('Earth curves'!$A$2:$A$46,MAX(1,MIN(44,IFERROR(MATCH(F5,'Earth curves'!$A$2:$A$46,1),1)))))) | S5: =MEDIAN(0.307692,Q5+MEDIAN(-0.350583,O5+NORMSINV(H5)*0.064828*Config!$B$3,0.120277),0.993846) | T5: =ROUND(Config!$B$7+(Config!$B$8-Config!$B$7)*S5,1) | V5: =IF(U5="",T5,U5) | W5: =MEDIAN(0.05,R5+MEDIAN(-0.302219,P5+NORMSINV(I5)*0.089531*Config!$B$3,0.274961),0.999) | X5: =(INDEX('Earth curves'!$F$2:$F$46,MAX(1,MIN(44,IFERROR(MATCH(W5,'Earth curves'!$E$2:$E$46,1),1))))+(W5-INDEX('Earth curves'!$E$2:$E$46,MAX(1,MIN(44,IFERROR(MATCH(W5,'Earth curves'!$E$2:$E$46,1),1)))))*(INDEX('Earth curves'!$F$2:$F$46,MAX(1,MIN(44,IFERROR(MATCH(W5,'Earth curves'!$E$2:$E$46,1),1)))+1)-INDEX('Earth curves'!$F$2:$F$46,MAX(1,MIN(44,IFERROR(MATCH(W5,'Earth curves'!$E$2:$E$46,1),1)))))/(INDEX('Earth curves'!$E$2:$E$46,MAX(1,MIN(44,IFERROR(MATCH(W5,'Earth curves'!$E$2:$E$46,1),1)))+1)-INDEX('Earth curves'!$E$2:$E$46,MAX(1,MIN(44,IFERROR(MATCH(W5,'Earth curves'!$E$2:$E$46,1),1)))))) | Y5: =(INDEX('Earth curves'!$G$2:$G$46,MAX(1,MIN(44,IFERROR(MATCH(W5,'Earth curves'!$E$2:$E$46,1),1))))+(W5-INDEX('Earth curves'!$E$2:$E$46,MAX(1,MIN(44,IFERROR(MATCH(W5,'Earth curves'!$E$2:$E$46,1),1)))))*(INDEX('Earth curves'!$G$2:$G$46,MAX(1,MIN(44,IFERROR(MATCH(W5,'Earth curves'!$E$2:$E$46,1),1)))+1)-INDEX('Earth curves'!$G$2:$G$46,MAX(1,MIN(44,IFERROR(MATCH(W5,'Earth curves'!$E$2:$E$46,1),1)))))/(INDEX('Earth curves'!$E$2:$E$46,MAX(1,MIN(44,IFERROR(MATCH(W5,'Earth curves'!$E$2:$E$46,1),1)))+1)-INDEX('Earth curves'!$E$2:$E$46,MAX(1,MIN(44,IFERROR(MATCH(W5,'Earth curves'!$E$2:$E$46,1),1)))))) | Z5: =(MIN(X5/Config!$B$9,1)+MIN(Y5/Config!$B$10,1))/2 | AA5: =ROUND(MIN(22,MAX(3,X5*W5/Z5)),1) | AC5: =IF(AB5="",AA5,AB5) | AD5: =ROUND(MIN(Config!$B$10,MAX(1,Y5*W5/Z5)),1) | AF5: =IF(AE5="",AD5,AE5) | AG5: =(V5-Config!$B$7)/(Config!$B$8-Config!$B$7) | AH5: =(MIN(AC5/Config!$B$9,1)+MIN(AF5/Config!$B$10,1))/2 | AI5: =ROUND((AG5*AH5*G5)^(1/3),3) | AJ5: 0.88 | AK5: =AI5-AJ5 | AL5: =AK5-AVERAGE($AK$2:$AK$173) | AM5: =IF(ABS(AL5)>Config!$B$11,"REVIEW","") | AN5: =RANK(AI5,$AI$2:$AI$173) | AO5: =RANK(AJ5,$AJ$2:$AJ$173) | AP5: 5
A6: Amcha | B6: Mahea | C6: militarised, resource | D6: 15333 | E6: =D6*Config!$B$4 | F6: =LN(MAX(60,E6)) | G6: =MEDIAN(0,(F6-LN(Config!$B$5))/(LN(Config!$B$6)-LN(Config!$B$5)),1) | H6: =MOD((Config!$B$2+$AP6*7919)*9301+49297,233280)/233280 | I6: =MOD((Config!$B$2+$AP6*104729)*4096+150889,714025)/714025 | J6: =MOD((Config!$B$2*31+$AP6*15485863)*1366+150889,714025)/714025 | M6: =COUNTIF(Siblings!$A$2:$A$84,B6) | N6: =1+INT(J6*M6) | O6: =IF(K6<>"",K6,IFERROR(INDEX(Siblings!$D$2:$D$84,MATCH(B6&"|"&N6,Siblings!$F$2:$F$84,0)),0)) | P6: =IF(L6<>"",L6,IFERROR(INDEX(Siblings!$E$2:$E$84,MATCH(B6&"|"&N6,Siblings!$F$2:$F$84,0)),0)) | Q6: =(INDEX('Earth curves'!$B$2:$B$46,MAX(1,MIN(44,IFERROR(MATCH(F6,'Earth curves'!$A$2:$A$46,1),1))))+(F6-INDEX('Earth curves'!$A$2:$A$46,MAX(1,MIN(44,IFERROR(MATCH(F6,'Earth curves'!$A$2:$A$46,1),1)))))*(INDEX('Earth curves'!$B$2:$B$46,MAX(1,MIN(44,IFERROR(MATCH(F6,'Earth curves'!$A$2:$A$46,1),1)))+1)-INDEX('Earth curves'!$B$2:$B$46,MAX(1,MIN(44,IFERROR(MATCH(F6,'Earth curves'!$A$2:$A$46,1),1)))))/(INDEX('Earth curves'!$A$2:$A$46,MAX(1,MIN(44,IFERROR(MATCH(F6,'Earth curves'!$A$2:$A$46,1),1)))+1)-INDEX('Earth curves'!$A$2:$A$46,MAX(1,MIN(44,IFERROR(MATCH(F6,'Earth curves'!$A$2:$A$46,1),1)))))) | R6: =(INDEX('Earth curves'!$C$2:$C$46,MAX(1,MIN(44,IFERROR(MATCH(F6,'Earth curves'!$A$2:$A$46,1),1))))+(F6-INDEX('Earth curves'!$A$2:$A$46,MAX(1,MIN(44,IFERROR(MATCH(F6,'Earth curves'!$A$2:$A$46,1),1)))))*(INDEX('Earth curves'!$C$2:$C$46,MAX(1,MIN(44,IFERROR(MATCH(F6,'Earth curves'!$A$2:$A$46,1),1)))+1)-INDEX('Earth curves'!$C$2:$C$46,MAX(1,MIN(44,IFERROR(MATCH(F6,'Earth curves'!$A$2:$A$46,1),1)))))/(INDEX('Earth curves'!$A$2:$A$46,MAX(1,MIN(44,IFERROR(MATCH(F6,'Earth curves'!$A$2:$A$46,1),1)))+1)-INDEX('Earth curves'!$A$2:$A$46,MAX(1,MIN(44,IFERROR(MATCH(F6,'Earth curves'!$A$2:$A$46,1),1)))))) | S6: =MEDIAN(0.307692,Q6+MEDIAN(-0.350583,O6+NORMSINV(H6)*0.064828*Config!$B$3,0.120277),0.993846) | T6: =ROUND(Config!$B$7+(Config!$B$8-Config!$B$7)*S6,1) | V6: =IF(U6="",T6,U6) | W6: =MEDIAN(0.05,R6+MEDIAN(-0.302219,P6+NORMSINV(I6)*0.089531*Config!$B$3,0.274961),0.999) | X6: =(INDEX('Earth curves'!$F$2:$F$46,MAX(1,MIN(44,IFERROR(MATCH(W6,'Earth curves'!$E$2:$E$46,1),1))))+(W6-INDEX('Earth curves'!$E$2:$E$46,MAX(1,MIN(44,IFERROR(MATCH(W6,'Earth curves'!$E$2:$E$46,1),1)))))*(INDEX('Earth curves'!$F$2:$F$46,MAX(1,MIN(44,IFERROR(MATCH(W6,'Earth curves'!$E$2:$E$46,1),1)))+1)-INDEX('Earth curves'!$F$2:$F$46,MAX(1,MIN(44,IFERROR(MATCH(W6,'Earth curves'!$E$2:$E$46,1),1)))))/(INDEX('Earth curves'!$E$2:$E$46,MAX(1,MIN(44,IFERROR(MATCH(W6,'Earth curves'!$E$2:$E$46,1),1)))+1)-INDEX('Earth curves'!$E$2:$E$46,MAX(1,MIN(44,IFERROR(MATCH(W6,'Earth curves'!$E$2:$E$46,1),1)))))) | Y6: =(INDEX('Earth curves'!$G$2:$G$46,MAX(1,MIN(44,IFERROR(MATCH(W6,'Earth curves'!$E$2:$E$46,1),1))))+(W6-INDEX('Earth curves'!$E$2:$E$46,MAX(1,MIN(44,IFERROR(MATCH(W6,'Earth curves'!$E$2:$E$46,1),1)))))*(INDEX('Earth curves'!$G$2:$G$46,MAX(1,MIN(44,IFERROR(MATCH(W6,'Earth curves'!$E$2:$E$46,1),1)))+1)-INDEX('Earth curves'!$G$2:$G$46,MAX(1,MIN(44,IFERROR(MATCH(W6,'Earth curves'!$E$2:$E$46,1),1)))))/(INDEX('Earth curves'!$E$2:$E$46,MAX(1,MIN(44,IFERROR(MATCH(W6,'Earth curves'!$E$2:$E$46,1),1)))+1)-INDEX('Earth curves'!$E$2:$E$46,MAX(1,MIN(44,IFERROR(MATCH(W6,'Earth curves'!$E$2:$E$46,1),1)))))) | Z6: =(MIN(X6/Config!$B$9,1)+MIN(Y6/Config!$B$10,1))/2 | AA6: =ROUND(MIN(22,MAX(3,X6*W6/Z6)),1) | AC6: =IF(AB6="",AA6,AB6) | AD6: =ROUND(MIN(Config!$B$10,MAX(1,Y6*W6/Z6)),1) | AF6: =IF(AE6="",AD6,AE6) | AG6: =(V6-Config!$B$7)/(Config!$B$8-Config!$B$7) | AH6: =(MIN(AC6/Config!$B$9,1)+MIN(AF6/Config!$B$10,1))/2 | AI6: =ROUND((AG6*AH6*G6)^(1/3),3) | AJ6: 0.688 | AK6: =AI6-AJ6 | AL6: =AK6-AVERAGE($AK$2:$AK$173) | AM6: =IF(ABS(AL6)>Config!$B$11,"REVIEW","") | AN6: =RANK(AI6,$AI$2:$AI$173) | AO6: =RANK(AJ6,$AJ$2:$AJ$173) | AP6: 6
A7: Andsaudare | B7: New Ayre | C7: militarised, resource | D7: 48889 | E7: =D7*Config!$B$4 | F7: =LN(MAX(60,E7)) | G7: =MEDIAN(0,(F7-LN(Config!$B$5))/(LN(Config!$B$6)-LN(Config!$B$5)),1) | H7: =MOD((Config!$B$2+$AP7*7919)*9301+49297,233280)/233280 | I7: =MOD((Config!$B$2+$AP7*104729)*4096+150889,714025)/714025 | J7: =MOD((Config!$B$2*31+$AP7*15485863)*1366+150889,714025)/714025 | M7: =COUNTIF(Siblings!$A$2:$A$84,B7) | N7: =1+INT(J7*M7) | O7: =IF(K7<>"",K7,IFERROR(INDEX(Siblings!$D$2:$D$84,MATCH(B7&"|"&N7,Siblings!$F$2:$F$84,0)),0)) | P7: =IF(L7<>"",L7,IFERROR(INDEX(Siblings!$E$2:$E$84,MATCH(B7&"|"&N7,Siblings!$F$2:$F$84,0)),0)) | Q7: =(INDEX('Earth curves'!$B$2:$B$46,MAX(1,MIN(44,IFERROR(MATCH(F7,'Earth curves'!$A$2:$A$46,1),1))))+(F7-INDEX('Earth curves'!$A$2:$A$46,MAX(1,MIN(44,IFERROR(MATCH(F7,'Earth curves'!$A$2:$A$46,1),1)))))*(INDEX('Earth curves'!$B$2:$B$46,MAX(1,MIN(44,IFERROR(MATCH(F7,'Earth curves'!$A$2:$A$46,1),1)))+1)-INDEX('Earth curves'!$B$2:$B$46,MAX(1,MIN(44,IFERROR(MATCH(F7,'Earth curves'!$A$2:$A$46,1),1)))))/(INDEX('Earth curves'!$A$2:$A$46,MAX(1,MIN(44,IFERROR(MATCH(F7,'Earth curves'!$A$2:$A$46,1),1)))+1)-INDEX('Earth curves'!$A$2:$A$46,MAX(1,MIN(44,IFERROR(MATCH(F7,'Earth curves'!$A$2:$A$46,1),1)))))) | R7: =(INDEX('Earth curves'!$C$2:$C$46,MAX(1,MIN(44,IFERROR(MATCH(F7,'Earth curves'!$A$2:$A$46,1),1))))+(F7-INDEX('Earth curves'!$A$2:$A$46,MAX(1,MIN(44,IFERROR(MATCH(F7,'Earth curves'!$A$2:$A$46,1),1)))))*(INDEX('Earth curves'!$C$2:$C$46,MAX(1,MIN(44,IFERROR(MATCH(F7,'Earth curves'!$A$2:$A$46,1),1)))+1)-INDEX('Earth curves'!$C$2:$C$46,MAX(1,MIN(44,IFERROR(MATCH(F7,'Earth curves'!$A$2:$A$46,1),1)))))/(INDEX('Earth curves'!$A$2:$A$46,MAX(1,MIN(44,IFERROR(MATCH(F7,'Earth curves'!$A$2:$A$46,1),1)))+1)-INDEX('Earth curves'!$A$2:$A$46,MAX(1,MIN(44,IFERROR(MATCH(F7,'Earth curves'!$A$2:$A$46,1),1)))))) | S7: =MEDIAN(0.307692,Q7+MEDIAN(-0.350583,O7+NORMSINV(H7)*0.064828*Config!$B$3,0.120277),0.993846) | T7: =ROUND(Config!$B$7+(Config!$B$8-Config!$B$7)*S7,1) | V7: =IF(U7="",T7,U7) | W7: =MEDIAN(0.05,R7+MEDIAN(-0.302219,P7+NORMSINV(I7)*0.089531*Config!$B$3,0.274961),0.999) | X7: =(INDEX('Earth curves'!$F$2:$F$46,MAX(1,MIN(44,IFERROR(MATCH(W7,'Earth curves'!$E$2:$E$46,1),1))))+(W7-INDEX('Earth curves'!$E$2:$E$46,MAX(1,MIN(44,IFERROR(MATCH(W7,'Earth curves'!$E$2:$E$46,1),1)))))*(INDEX('Earth curves'!$F$2:$F$46,MAX(1,MIN(44,IFERROR(MATCH(W7,'Earth curves'!$E$2:$E$46,1),1)))+1)-INDEX('Earth curves'!$F$2:$F$46,MAX(1,MIN(44,IFERROR(MATCH(W7,'Earth curves'!$E$2:$E$46,1),1)))))/(INDEX('Earth curves'!$E$2:$E$46,MAX(1,MIN(44,IFERROR(MATCH(W7,'Earth curves'!$E$2:$E$46,1),1)))+1)-INDEX('Earth curves'!$E$2:$E$46,MAX(1,MIN(44,IFERROR(MATCH(W7,'Earth curves'!$E$2:$E$46,1),1)))))) | Y7: =(INDEX('Earth curves'!$G$2:$G$46,MAX(1,MIN(44,IFERROR(MATCH(W7,'Earth curves'!$E$2:$E$46,1),1))))+(W7-INDEX('Earth curves'!$E$2:$E$46,MAX(1,MIN(44,IFERROR(MATCH(W7,'Earth curves'!$E$2:$E$46,1),1)))))*(INDEX('Earth curves'!$G$2:$G$46,MAX(1,MIN(44,IFERROR(MATCH(W7,'Earth curves'!$E$2:$E$46,1),1)))+1)-INDEX('Earth curves'!$G$2:$G$46,MAX(1,MIN(44,IFERROR(MATCH(W7,'Earth curves'!$E$2:$E$46,1),1)))))/(INDEX('Earth curves'!$E$2:$E$46,MAX(1,MIN(44,IFERROR(MATCH(W7,'Earth curves'!$E$2:$E$46,1),1)))+1)-INDEX('Earth curves'!$E$2:$E$46,MAX(1,MIN(44,IFERROR(MATCH(W7,'Earth curves'!$E$2:$E$46,1),1)))))) | Z7: =(MIN(X7/Config!$B$9,1)+MIN(Y7/Config!$B$10,1))/2 | AA7: =ROUND(MIN(22,MAX(3,X7*W7/Z7)),1) | AC7: =IF(AB7="",AA7,AB7) | AD7: =ROUND(MIN(Config!$B$10,MAX(1,Y7*W7/Z7)),1) | AF7: =IF(AE7="",AD7,AE7) | AG7: =(V7-Config!$B$7)/(Config!$B$8-Config!$B$7) | AH7: =(MIN(AC7/Config!$B$9,1)+MIN(AF7/Config!$B$10,1))/2 | AI7: =ROUND((AG7*AH7*G7)^(1/3),3) | AJ7: 0.803 | AK7: =AI7-AJ7 | AL7: =AK7-AVERAGE($AK$2:$AK$173) | AM7: =IF(ABS(AL7)>Config!$B$11,"REVIEW","") | AN7: =RANK(AI7,$AI$2:$AI$173) | AO7: =RANK(AJ7,$AJ$2:$AJ$173) | AP7: 7
A8: Anymna | B8: Quia | C8: resource | D8: 86032 | E8: =D8*Config!$B$4 | F8: =LN(MAX(60,E8)) | G8: =MEDIAN(0,(F8-LN(Config!$B$5))/(LN(Config!$B$6)-LN(Config!$B$5)),1) | H8: =MOD((Config!$B$2+$AP8*7919)*9301+49297,233280)/233280 | I8: =MOD((Config!$B$2+$AP8*104729)*4096+150889,714025)/714025 | J8: =MOD((Config!$B$2*31+$AP8*15485863)*1366+150889,714025)/714025 | M8: =COUNTIF(Siblings!$A$2:$A$84,B8) | N8: =1+INT(J8*M8) | O8: =IF(K8<>"",K8,IFERROR(INDEX(Siblings!$D$2:$D$84,MATCH(B8&"|"&N8,Siblings!$F$2:$F$84,0)),0)) | P8: =IF(L8<>"",L8,IFERROR(INDEX(Siblings!$E$2:$E$84,MATCH(B8&"|"&N8,Siblings!$F$2:$F$84,0)),0)) | Q8: =(INDEX('Earth curves'!$B$2:$B$46,MAX(1,MIN(44,IFERROR(MATCH(F8,'Earth curves'!$A$2:$A$46,1),1))))+(F8-INDEX('Earth curves'!$A$2:$A$46,MAX(1,MIN(44,IFERROR(MATCH(F8,'Earth curves'!$A$2:$A$46,1),1)))))*(INDEX('Earth curves'!$B$2:$B$46,MAX(1,MIN(44,IFERROR(MATCH(F8,'Earth curves'!$A$2:$A$46,1),1)))+1)-INDEX('Earth curves'!$B$2:$B$46,MAX(1,MIN(44,IFERROR(MATCH(F8,'Earth curves'!$A$2:$A$46,1),1)))))/(INDEX('Earth curves'!$A$2:$A$46,MAX(1,MIN(44,IFERROR(MATCH(F8,'Earth curves'!$A$2:$A$46,1),1)))+1)-INDEX('Earth curves'!$A$2:$A$46,MAX(1,MIN(44,IFERROR(MATCH(F8,'Earth curves'!$A$2:$A$46,1),1)))))) | R8: =(INDEX('Earth curves'!$C$2:$C$46,MAX(1,MIN(44,IFERROR(MATCH(F8,'Earth curves'!$A$2:$A$46,1),1))))+(F8-INDEX('Earth curves'!$A$2:$A$46,MAX(1,MIN(44,IFERROR(MATCH(F8,'Earth curves'!$A$2:$A$46,1),1)))))*(INDEX('Earth curves'!$C$2:$C$46,MAX(1,MIN(44,IFERROR(MATCH(F8,'Earth curves'!$A$2:$A$46,1),1)))+1)-INDEX('Earth curves'!$C$2:$C$46,MAX(1,MIN(44,IFERROR(MATCH(F8,'Earth curves'!$A$2:$A$46,1),1)))))/(INDEX('Earth curves'!$A$2:$A$46,MAX(1,MIN(44,IFERROR(MATCH(F8,'Earth curves'!$A$2:$A$46,1),1)))+1)-INDEX('Earth curves'!$A$2:$A$46,MAX(1,MIN(44,IFERROR(MATCH(F8,'Earth curves'!$A$2:$A$46,1),1)))))) | S8: =MEDIAN(0.307692,Q8+MEDIAN(-0.350583,O8+NORMSINV(H8)*0.064828*Config!$B$3,0.120277),0.993846) | T8: =ROUND(Config!$B$7+(Config!$B$8-Config!$B$7)*S8,1) | V8: =IF(U8="",T8,U8) | W8: =MEDIAN(0.05,R8+MEDIAN(-0.302219,P8+NORMSINV(I8)*0.089531*Config!$B$3,0.274961),0.999) | X8: =(INDEX('Earth curves'!$F$2:$F$46,MAX(1,MIN(44,IFERROR(MATCH(W8,'Earth curves'!$E$2:$E$46,1),1))))+(W8-INDEX('Earth curves'!$E$2:$E$46,MAX(1,MIN(44,IFERROR(MATCH(W8,'Earth curves'!$E$2:$E$46,1),1)))))*(INDEX('Earth curves'!$F$2:$F$46,MAX(1,MIN(44,IFERROR(MATCH(W8,'Earth curves'!$E$2:$E$46,1),1)))+1)-INDEX('Earth curves'!$F$2:$F$46,MAX(1,MIN(44,IFERROR(MATCH(W8,'Earth curves'!$E$2:$E$46,1),1)))))/(INDEX('Earth curves'!$E$2:$E$46,MAX(1,MIN(44,IFERROR(MATCH(W8,'Earth curves'!$E$2:$E$46,1),1)))+1)-INDEX('Earth curves'!$E$2:$E$46,MAX(1,MIN(44,IFERROR(MATCH(W8,'Earth curves'!$E$2:$E$46,1),1)))))) | Y8: =(INDEX('Earth curves'!$G$2:$G$46,MAX(1,MIN(44,IFERROR(MATCH(W8,'Earth curves'!$E$2:$E$46,1),1))))+(W8-INDEX('Earth curves'!$E$2:$E$46,MAX(1,MIN(44,IFERROR(MATCH(W8,'Earth curves'!$E$2:$E$46,1),1)))))*(INDEX('Earth curves'!$G$2:$G$46,MAX(1,MIN(44,IFERROR(MATCH(W8,'Earth curves'!$E$2:$E$46,1),1)))+1)-INDEX('Earth curves'!$G$2:$G$46,MAX(1,MIN(44,IFERROR(MATCH(W8,'Earth curves'!$E$2:$E$46,1),1)))))/(INDEX('Earth curves'!$E$2:$E$46,MAX(1,MIN(44,IFERROR(MATCH(W8,'Earth curves'!$E$2:$E$46,1),1)))+1)-INDEX('Earth curves'!$E$2:$E$46,MAX(1,MIN(44,IFERROR(MATCH(W8,'Earth curves'!$E$2:$E$46,1),1)))))) | Z8: =(MIN(X8/Config!$B$9,1)+MIN(Y8/Config!$B$10,1))/2 | AA8: =ROUND(MIN(22,MAX(3,X8*W8/Z8)),1) | AC8: =IF(AB8="",AA8,AB8) | AD8: =ROUND(MIN(Config!$B$10,MAX(1,Y8*W8/Z8)),1) | AF8: =IF(AE8="",AD8,AE8) | AG8: =(V8-Config!$B$7)/(Config!$B$8-Config!$B$7) | AH8: =(MIN(AC8/Config!$B$9,1)+MIN(AF8/Config!$B$10,1))/2 | AI8: =ROUND((AG8*AH8*G8)^(1/3),3) | AJ8: 0.79 | AK8: =AI8-AJ8 | AL8: =AK8-AVERAGE($AK$2:$AK$173) | AM8: =IF(ABS(AL8)>Config!$B$11,"REVIEW","") | AN8: =RANK(AI8,$AI$2:$AI$173) | AO8: =RANK(AJ8,$AJ$2:$AJ$173) | AP8: 8
A9: Aplasia | B9: New Ayre | C9: — | D9: 151746 | E9: =D9*Config!$B$4 | F9: =LN(MAX(60,E9)) | G9: =MEDIAN(0,(F9-LN(Config!$B$5))/(LN(Config!$B$6)-LN(Config!$B$5)),1) | H9: =MOD((Config!$B$2+$AP9*7919)*9301+49297,233280)/233280 | I9: =MOD((Config!$B$2+$AP9*104729)*4096+150889,714025)/714025 | J9: =MOD((Config!$B$2*31+$AP9*15485863)*1366+150889,714025)/714025 | M9: =COUNTIF(Siblings!$A$2:$A$84,B9) | N9: =1+INT(J9*M9) | O9: =IF(K9<>"",K9,IFERROR(INDEX(Siblings!$D$2:$D$84,MATCH(B9&"|"&N9,Siblings!$F$2:$F$84,0)),0)) | P9: =IF(L9<>"",L9,IFERROR(INDEX(Siblings!$E$2:$E$84,MATCH(B9&"|"&N9,Siblings!$F$2:$F$84,0)),0)) | Q9: =(INDEX('Earth curves'!$B$2:$B$46,MAX(1,MIN(44,IFERROR(MATCH(F9,'Earth curves'!$A$2:$A$46,1),1))))+(F9-INDEX('Earth curves'!$A$2:$A$46,MAX(1,MIN(44,IFERROR(MATCH(F9,'Earth curves'!$A$2:$A$46,1),1)))))*(INDEX('Earth curves'!$B$2:$B$46,MAX(1,MIN(44,IFERROR(MATCH(F9,'Earth curves'!$A$2:$A$46,1),1)))+1)-INDEX('Earth curves'!$B$2:$B$46,MAX(1,MIN(44,IFERROR(MATCH(F9,'Earth curves'!$A$2:$A$46,1),1)))))/(INDEX('Earth curves'!$A$2:$A$46,MAX(1,MIN(44,IFERROR(MATCH(F9,'Earth curves'!$A$2:$A$46,1),1)))+1)-INDEX('Earth curves'!$A$2:$A$46,MAX(1,MIN(44,IFERROR(MATCH(F9,'Earth curves'!$A$2:$A$46,1),1)))))) | R9: =(INDEX('Earth curves'!$C$2:$C$46,MAX(1,MIN(44,IFERROR(MATCH(F9,'Earth curves'!$A$2:$A$46,1),1))))+(F9-INDEX('Earth curves'!$A$2:$A$46,MAX(1,MIN(44,IFERROR(MATCH(F9,'Earth curves'!$A$2:$A$46,1),1)))))*(INDEX('Earth curves'!$C$2:$C$46,MAX(1,MIN(44,IFERROR(MATCH(F9,'Earth curves'!$A$2:$A$46,1),1)))+1)-INDEX('Earth curves'!$C$2:$C$46,MAX(1,MIN(44,IFERROR(MATCH(F9,'Earth curves'!$A$2:$A$46,1),1)))))/(INDEX('Earth curves'!$A$2:$A$46,MAX(1,MIN(44,IFERROR(MATCH(F9,'Earth curves'!$A$2:$A$46,1),1)))+1)-INDEX('Earth curves'!$A$2:$A$46,MAX(1,MIN(44,IFERROR(MATCH(F9,'Earth curves'!$A$2:$A$46,1),1)))))) | S9: =MEDIAN(0.307692,Q9+MEDIAN(-0.350583,O9+NORMSINV(H9)*0.064828*Config!$B$3,0.120277),0.993846) | T9: =ROUND(Config!$B$7+(Config!$B$8-Config!$B$7)*S9,1) | V9: =IF(U9="",T9,U9) | W9: =MEDIAN(0.05,R9+MEDIAN(-0.302219,P9+NORMSINV(I9)*0.089531*Config!$B$3,0.274961),0.999) | X9: =(INDEX('Earth curves'!$F$2:$F$46,MAX(1,MIN(44,IFERROR(MATCH(W9,'Earth curves'!$E$2:$E$46,1),1))))+(W9-INDEX('Earth curves'!$E$2:$E$46,MAX(1,MIN(44,IFERROR(MATCH(W9,'Earth curves'!$E$2:$E$46,1),1)))))*(INDEX('Earth curves'!$F$2:$F$46,MAX(1,MIN(44,IFERROR(MATCH(W9,'Earth curves'!$E$2:$E$46,1),1)))+1)-INDEX('Earth curves'!$F$2:$F$46,MAX(1,MIN(44,IFERROR(MATCH(W9,'Earth curves'!$E$2:$E$46,1),1)))))/(INDEX('Earth curves'!$E$2:$E$46,MAX(1,MIN(44,IFERROR(MATCH(W9,'Earth curves'!$E$2:$E$46,1),1)))+1)-INDEX('Earth curves'!$E$2:$E$46,MAX(1,MIN(44,IFERROR(MATCH(W9,'Earth curves'!$E$2:$E$46,1),1)))))) | Y9: =(INDEX('Earth curves'!$G$2:$G$46,MAX(1,MIN(44,IFERROR(MATCH(W9,'Earth curves'!$E$2:$E$46,1),1))))+(W9-INDEX('Earth curves'!$E$2:$E$46,MAX(1,MIN(44,IFERROR(MATCH(W9,'Earth curves'!$E$2:$E$46,1),1)))))*(INDEX('Earth curves'!$G$2:$G$46,MAX(1,MIN(44,IFERROR(MATCH(W9,'Earth curves'!$E$2:$E$46,1),1)))+1)-INDEX('Earth curves'!$G$2:$G$46,MAX(1,MIN(44,IFERROR(MATCH(W9,'Earth curves'!$E$2:$E$46,1),1)))))/(INDEX('Earth curves'!$E$2:$E$46,MAX(1,MIN(44,IFERROR(MATCH(W9,'Earth curves'!$E$2:$E$46,1),1)))+1)-INDEX('Earth curves'!$E$2:$E$46,MAX(1,MIN(44,IFERROR(MATCH(W9,'Earth curves'!$E$2:$E$46,1),1)))))) | Z9: =(MIN(X9/Config!$B$9,1)+MIN(Y9/Config!$B$10,1))/2 | AA9: =ROUND(MIN(22,MAX(3,X9*W9/Z9)),1) | AC9: =IF(AB9="",AA9,AB9) | AD9: =ROUND(MIN(Config!$B$10,MAX(1,Y9*W9/Z9)),1) | AF9: =IF(AE9="",AD9,AE9) | AG9: =(V9-Config!$B$7)/(Config!$B$8-Config!$B$7) | AH9: =(MIN(AC9/Config!$B$9,1)+MIN(AF9/Config!$B$10,1))/2 | AI9: =ROUND((AG9*AH9*G9)^(1/3),3) | AJ9: 0.763 | AK9: =AI9-AJ9 | AL9: =AK9-AVERAGE($AK$2:$AK$173) | AM9: =IF(ABS(AL9)>Config!$B$11,"REVIEW","") | AN9: =RANK(AI9,$AI$2:$AI$173) | AO9: =RANK(AJ9,$AJ$2:$AJ$173) | AP9: 9
A10: Arbiya | B10: Atirha | C10: resource | D10: 116825 | E10: =D10*Config!$B$4 | F10: =LN(MAX(60,E10)) | G10: =MEDIAN(0,(F10-LN(Config!$B$5))/(LN(Config!$B$6)-LN(Config!$B$5)),1) | H10: =MOD((Config!$B$2+$AP10*7919)*9301+49297,233280)/233280 | I10: =MOD((Config!$B$2+$AP10*104729)*4096+150889,714025)/714025 | J10: =MOD((Config!$B$2*31+$AP10*15485863)*1366+150889,714025)/714025 | K10: -0.043414 | L10: 0.06729 | M10: =COUNTIF(Siblings!$A$2:$A$84,B10) | N10: =1+INT(J10*M10) | O10: =IF(K10<>"",K10,IFERROR(INDEX(Siblings!$D$2:$D$84,MATCH(B10&"|"&N10,Siblings!$F$2:$F$84,0)),0)) | P10: =IF(L10<>"",L10,IFERROR(INDEX(Siblings!$E$2:$E$84,MATCH(B10&"|"&N10,Siblings!$F$2:$F$84,0)),0)) | Q10: =(INDEX('Earth curves'!$B$2:$B$46,MAX(1,MIN(44,IFERROR(MATCH(F10,'Earth curves'!$A$2:$A$46,1),1))))+(F10-INDEX('Earth curves'!$A$2:$A$46,MAX(1,MIN(44,IFERROR(MATCH(F10,'Earth curves'!$A$2:$A$46,1),1)))))*(INDEX('Earth curves'!$B$2:$B$46,MAX(1,MIN(44,IFERROR(MATCH(F10,'Earth curves'!$A$2:$A$46,1),1)))+1)-INDEX('Earth curves'!$B$2:$B$46,MAX(1,MIN(44,IFERROR(MATCH(F10,'Earth curves'!$A$2:$A$46,1),1)))))/(INDEX('Earth curves'!$A$2:$A$46,MAX(1,MIN(44,IFERROR(MATCH(F10,'Earth curves'!$A$2:$A$46,1),1)))+1)-INDEX('Earth curves'!$A$2:$A$46,MAX(1,MIN(44,IFERROR(MATCH(F10,'Earth curves'!$A$2:$A$46,1),1)))))) | R10: =(INDEX('Earth curves'!$C$2:$C$46,MAX(1,MIN(44,IFERROR(MATCH(F10,'Earth curves'!$A$2:$A$46,1),1))))+(F10-INDEX('Earth curves'!$A$2:$A$46,MAX(1,MIN(44,IFERROR(MATCH(F10,'Earth curves'!$A$2:$A$46,1),1)))))*(INDEX('Earth curves'!$C$2:$C$46,MAX(1,MIN(44,IFERROR(MATCH(F10,'Earth curves'!$A$2:$A$46,1),1)))+1)-INDEX('Earth curves'!$C$2:$C$46,MAX(1,MIN(44,IFERROR(MATCH(F10,'Earth curves'!$A$2:$A$46,1),1)))))/(INDEX('Earth curves'!$A$2:$A$46,MAX(1,MIN(44,IFERROR(MATCH(F10,'Earth curves'!$A$2:$A$46,1),1)))+1)-INDEX('Earth curves'!$A$2:$A$46,MAX(1,MIN(44,IFERROR(MATCH(F10,'Earth curves'!$A$2:$A$46,1),1)))))) | S10: =MEDIAN(0.307692,Q10+MEDIAN(-0.350583,O10+NORMSINV(H10)*0.064828*Config!$B$3,0.120277),0.993846) | T10: =ROUND(Config!$B$7+(Config!$B$8-Config!$B$7)*S10,1) | V10: =IF(U10="",T10,U10) | W10: =MEDIAN(0.05,R10+MEDIAN(-0.302219,P10+NORMSINV(I10)*0.089531*Config!$B$3,0.274961),0.999) | X10: =(INDEX('Earth curves'!$F$2:$F$46,MAX(1,MIN(44,IFERROR(MATCH(W10,'Earth curves'!$E$2:$E$46,1),1))))+(W10-INDEX('Earth curves'!$E$2:$E$46,MAX(1,MIN(44,IFERROR(MATCH(W10,'Earth curves'!$E$2:$E$46,1),1)))))*(INDEX('Earth curves'!$F$2:$F$46,MAX(1,MIN(44,IFERROR(MATCH(W10,'Earth curves'!$E$2:$E$46,1),1)))+1)-INDEX('Earth curves'!$F$2:$F$46,MAX(1,MIN(44,IFERROR(MATCH(W10,'Earth curves'!$E$2:$E$46,1),1)))))/(INDEX('Earth curves'!$E$2:$E$46,MAX(1,MIN(44,IFERROR(MATCH(W10,'Earth curves'!$E$2:$E$46,1),1)))+1)-INDEX('Earth curves'!$E$2:$E$46,MAX(1,MIN(44,IFERROR(MATCH(W10,'Earth curves'!$E$2:$E$46,1),1)))))) | Y10: =(INDEX('Earth curves'!$G$2:$G$46,MAX(1,MIN(44,IFERROR(MATCH(W10,'Earth curves'!$E$2:$E$46,1),1))))+(W10-INDEX('Earth curves'!$E$2:$E$46,MAX(1,MIN(44,IFERROR(MATCH(W10,'Earth curves'!$E$2:$E$46,1),1)))))*(INDEX('Earth curves'!$G$2:$G$46,MAX(1,MIN(44,IFERROR(MATCH(W10,'Earth curves'!$E$2:$E$46,1),1)))+1)-INDEX('Earth curves'!$G$2:$G$46,MAX(1,MIN(44,IFERROR(MATCH(W10,'Earth curves'!$E$2:$E$46,1),1)))))/(INDEX('Earth curves'!$E$2:$E$46,MAX(1,MIN(44,IFERROR(MATCH(W10,'Earth curves'!$E$2:$E$46,1),1)))+1)-INDEX('Earth curves'!$E$2:$E$46,MAX(1,MIN(44,IFERROR(MATCH(W10,'Earth curves'!$E$2:$E$46,1),1)))))) | Z10: =(MIN(X10/Config!$B$9,1)+MIN(Y10/Config!$B$10,1))/2 | AA10: =ROUND(MIN(22,MAX(3,X10*W10/Z10)),1) | AC10: =IF(AB10="",AA10,AB10) | AD10: =ROUND(MIN(Config!$B$10,MAX(1,Y10*W10/Z10)),1) | AF10: =IF(AE10="",AD10,AE10) | AG10: =(V10-Config!$B$7)/(Config!$B$8-Config!$B$7) | AH10: =(MIN(AC10/Config!$B$9,1)+MIN(AF10/Config!$B$10,1))/2 | AI10: =ROUND((AG10*AH10*G10)^(1/3),3) | AJ10: 0.862 | AK10: =AI10-AJ10 | AL10: =AK10-AVERAGE($AK$2:$AK$173) | AM10: =IF(ABS(AL10)>Config!$B$11,"REVIEW","") | AN10: =RANK(AI10,$AI$2:$AI$173) | AO10: =RANK(AJ10,$AJ$2:$AJ$173) | AP10: 10
A11: Areoix Lie | B11: Acrola | C11: petro, resource, tradehub, university | D11: 63492 | E11: =D11*Config!$B$4 | F11: =LN(MAX(60,E11)) | G11: =MEDIAN(0,(F11-LN(Config!$B$5))/(LN(Config!$B$6)-LN(Config!$B$5)),1) | H11: =MOD((Config!$B$2+$AP11*7919)*9301+49297,233280)/233280 | I11: =MOD((Config!$B$2+$AP11*104729)*4096+150889,714025)/714025 | J11: =MOD((Config!$B$2*31+$AP11*15485863)*1366+150889,714025)/714025 | M11: =COUNTIF(Siblings!$A$2:$A$84,B11) | N11: =1+INT(J11*M11) | O11: =IF(K11<>"",K11,IFERROR(INDEX(Siblings!$D$2:$D$84,MATCH(B11&"|"&N11,Siblings!$F$2:$F$84,0)),0)) | P11: =IF(L11<>"",L11,IFERROR(INDEX(Siblings!$E$2:$E$84,MATCH(B11&"|"&N11,Siblings!$F$2:$F$84,0)),0)) | Q11: =(INDEX('Earth curves'!$B$2:$B$46,MAX(1,MIN(44,IFERROR(MATCH(F11,'Earth curves'!$A$2:$A$46,1),1))))+(F11-INDEX('Earth curves'!$A$2:$A$46,MAX(1,MIN(44,IFERROR(MATCH(F11,'Earth curves'!$A$2:$A$46,1),1)))))*(INDEX('Earth curves'!$B$2:$B$46,MAX(1,MIN(44,IFERROR(MATCH(F11,'Earth curves'!$A$2:$A$46,1),1)))+1)-INDEX('Earth curves'!$B$2:$B$46,MAX(1,MIN(44,IFERROR(MATCH(F11,'Earth curves'!$A$2:$A$46,1),1)))))/(INDEX('Earth curves'!$A$2:$A$46,MAX(1,MIN(44,IFERROR(MATCH(F11,'Earth curves'!$A$2:$A$46,1),1)))+1)-INDEX('Earth curves'!$A$2:$A$46,MAX(1,MIN(44,IFERROR(MATCH(F11,'Earth curves'!$A$2:$A$46,1),1)))))) | R11: =(INDEX('Earth curves'!$C$2:$C$46,MAX(1,MIN(44,IFERROR(MATCH(F11,'Earth curves'!$A$2:$A$46,1),1))))+(F11-INDEX('Earth curves'!$A$2:$A$46,MAX(1,MIN(44,IFERROR(MATCH(F11,'Earth curves'!$A$2:$A$46,1),1)))))*(INDEX('Earth curves'!$C$2:$C$46,MAX(1,MIN(44,IFERROR(MATCH(F11,'Earth curves'!$A$2:$A$46,1),1)))+1)-INDEX('Earth curves'!$C$2:$C$46,MAX(1,MIN(44,IFERROR(MATCH(F11,'Earth curves'!$A$2:$A$46,1),1)))))/(INDEX('Earth curves'!$A$2:$A$46,MAX(1,MIN(44,IFERROR(MATCH(F11,'Earth curves'!$A$2:$A$46,1),1)))+1)-INDEX('Earth curves'!$A$2:$A$46,MAX(1,MIN(44,IFERROR(MATCH(F11,'Earth curves'!$A$2:$A$46,1),1)))))) | S11: =MEDIAN(0.307692,Q11+MEDIAN(-0.350583,O11+NORMSINV(H11)*0.064828*Config!$B$3,0.120277),0.993846) | T11: =ROUND(Config!$B$7+(Config!$B$8-Config!$B$7)*S11,1) | V11: =IF(U11="",T11,U11) | W11: =MEDIAN(0.05,R11+MEDIAN(-0.302219,P11+NORMSINV(I11)*0.089531*Config!$B$3,0.274961),0.999) | X11: =(INDEX('Earth curves'!$F$2:$F$46,MAX(1,MIN(44,IFERROR(MATCH(W11,'Earth curves'!$E$2:$E$46,1),1))))+(W11-INDEX('Earth curves'!$E$2:$E$46,MAX(1,MIN(44,IFERROR(MATCH(W11,'Earth curves'!$E$2:$E$46,1),1)))))*(INDEX('Earth curves'!$F$2:$F$46,MAX(1,MIN(44,IFERROR(MATCH(W11,'Earth curves'!$E$2:$E$46,1),1)))+1)-INDEX('Earth curves'!$F$2:$F$46,MAX(1,MIN(44,IFERROR(MATCH(W11,'Earth curves'!$E$2:$E$46,1),1)))))/(INDEX('Earth curves'!$E$2:$E$46,MAX(1,MIN(44,IFERROR(MATCH(W11,'Earth curves'!$E$2:$E$46,1),1)))+1)-INDEX('Earth curves'!$E$2:$E$46,MAX(1,MIN(44,IFERROR(MATCH(W11,'Earth curves'!$E$2:$E$46,1),1)))))) | Y11: =(INDEX('Earth curves'!$G$2:$G$46,MAX(1,MIN(44,IFERROR(MATCH(W11,'Earth curves'!$E$2:$E$46,1),1))))+(W11-INDEX('Earth curves'!$E$2:$E$46,MAX(1,MIN(44,IFERROR(MATCH(W11,'Earth curves'!$E$2:$E$46,1),1)))))*(INDEX('Earth curves'!$G$2:$G$46,MAX(1,MIN(44,IFERROR(MATCH(W11,'Earth curves'!$E$2:$E$46,1),1)))+1)-INDEX('Earth curves'!$G$2:$G$46,MAX(1,MIN(44,IFERROR(MATCH(W11,'Earth curves'!$E$2:$E$46,1),1)))))/(INDEX('Earth curves'!$E$2:$E$46,MAX(1,MIN(44,IFERROR(MATCH(W11,'Earth curves'!$E$2:$E$46,1),1)))+1)-INDEX('Earth curves'!$E$2:$E$46,MAX(1,MIN(44,IFERROR(MATCH(W11,'Earth curves'!$E$2:$E$46,1),1)))))) | Z11: =(MIN(X11/Config!$B$9,1)+MIN(Y11/Config!$B$10,1))/2 | AA11: =ROUND(MIN(22,MAX(3,X11*W11/Z11)),1) | AC11: =IF(AB11="",AA11,AB11) | AD11: =ROUND(MIN(Config!$B$10,MAX(1,Y11*W11/Z11)),1) | AF11: =IF(AE11="",AD11,AE11) | AG11: =(V11-Config!$B$7)/(Config!$B$8-Config!$B$7) | AH11: =(MIN(AC11/Config!$B$9,1)+MIN(AF11/Config!$B$10,1))/2 | AI11: =ROUND((AG11*AH11*G11)^(1/3),3) | AJ11: 0.712 | AK11: =AI11-AJ11 | AL11: =AK11-AVERAGE($AK$2:$AK$173) | AM11: =IF(ABS(AL11)>Config!$B$11,"REVIEW","") | AN11: =RANK(AI11,$AI$2:$AI$173) | AO11: =RANK(AJ11,$AJ$2:$AJ$173) | AP11: 11
A12: Ashain | B12: Quia | C12: petro, resource, university | D12: 101905 | E12: =D12*Config!$B$4 | F12: =LN(MAX(60,E12)) | G12: =MEDIAN(0,(F12-LN(Config!$B$5))/(LN(Config!$B$6)-LN(Config!$B$5)),1) | H12: =MOD((Config!$B$2+$AP12*7919)*9301+49297,233280)/233280 | I12: =MOD((Config!$B$2+$AP12*104729)*4096+150889,714025)/714025 | J12: =MOD((Config!$B$2*31+$AP12*15485863)*1366+150889,714025)/714025 | M12: =COUNTIF(Siblings!$A$2:$A$84,B12) | N12: =1+INT(J12*M12) | O12: =IF(K12<>"",K12,IFERROR(INDEX(Siblings!$D$2:$D$84,MATCH(B12&"|"&N12,Siblings!$F$2:$F$84,0)),0)) | P12: =IF(L12<>"",L12,IFERROR(INDEX(Siblings!$E$2:$E$84,MATCH(B12&"|"&N12,Siblings!$F$2:$F$84,0)),0)) | Q12: =(INDEX('Earth curves'!$B$2:$B$46,MAX(1,MIN(44,IFERROR(MATCH(F12,'Earth curves'!$A$2:$A$46,1),1))))+(F12-INDEX('Earth curves'!$A$2:$A$46,MAX(1,MIN(44,IFERROR(MATCH(F12,'Earth curves'!$A$2:$A$46,1),1)))))*(INDEX('Earth curves'!$B$2:$B$46,MAX(1,MIN(44,IFERROR(MATCH(F12,'Earth curves'!$A$2:$A$46,1),1)))+1)-INDEX('Earth curves'!$B$2:$B$46,MAX(1,MIN(44,IFERROR(MATCH(F12,'Earth curves'!$A$2:$A$46,1),1)))))/(INDEX('Earth curves'!$A$2:$A$46,MAX(1,MIN(44,IFERROR(MATCH(F12,'Earth curves'!$A$2:$A$46,1),1)))+1)-INDEX('Earth curves'!$A$2:$A$46,MAX(1,MIN(44,IFERROR(MATCH(F12,'Earth curves'!$A$2:$A$46,1),1)))))) | R12: =(INDEX('Earth curves'!$C$2:$C$46,MAX(1,MIN(44,IFERROR(MATCH(F12,'Earth curves'!$A$2:$A$46,1),1))))+(F12-INDEX('Earth curves'!$A$2:$A$46,MAX(1,MIN(44,IFERROR(MATCH(F12,'Earth curves'!$A$2:$A$46,1),1)))))*(INDEX('Earth curves'!$C$2:$C$46,MAX(1,MIN(44,IFERROR(MATCH(F12,'Earth curves'!$A$2:$A$46,1),1)))+1)-INDEX('Earth curves'!$C$2:$C$46,MAX(1,MIN(44,IFERROR(MATCH(F12,'Earth curves'!$A$2:$A$46,1),1)))))/(INDEX('Earth curves'!$A$2:$A$46,MAX(1,MIN(44,IFERROR(MATCH(F12,'Earth curves'!$A$2:$A$46,1),1)))+1)-INDEX('Earth curves'!$A$2:$A$46,MAX(1,MIN(44,IFERROR(MATCH(F12,'Earth curves'!$A$2:$A$46,1),1)))))) | S12: =MEDIAN(0.307692,Q12+MEDIAN(-0.350583,O12+NORMSINV(H12)*0.064828*Config!$B$3,0.120277),0.993846) | T12: =ROUND(Config!$B$7+(Config!$B$8-Config!$B$7)*S12,1) | V12: =IF(U12="",T12,U12) | W12: =MEDIAN(0.05,R12+MEDIAN(-0.302219,P12+NORMSINV(I12)*0.089531*Config!$B$3,0.274961),0.999) | X12: =(INDEX('Earth curves'!$F$2:$F$46,MAX(1,MIN(44,IFERROR(MATCH(W12,'Earth curves'!$E$2:$E$46,1),1))))+(W12-INDEX('Earth curves'!$E$2:$E$46,MAX(1,MIN(44,IFERROR(MATCH(W12,'Earth curves'!$E$2:$E$46,1),1)))))*(INDEX('Earth curves'!$F$2:$F$46,MAX(1,MIN(44,IFERROR(MATCH(W12,'Earth curves'!$E$2:$E$46,1),1)))+1)-INDEX('Earth curves'!$F$2:$F$46,MAX(1,MIN(44,IFERROR(MATCH(W12,'Earth curves'!$E$2:$E$46,1),1)))))/(INDEX('Earth curves'!$E$2:$E$46,MAX(1,MIN(44,IFERROR(MATCH(W12,'Earth curves'!$E$2:$E$46,1),1)))+1)-INDEX('Earth curves'!$E$2:$E$46,MAX(1,MIN(44,IFERROR(MATCH(W12,'Earth curves'!$E$2:$E$46,1),1)))))) | Y12: =(INDEX('Earth curves'!$G$2:$G$46,MAX(1,MIN(44,IFERROR(MATCH(W12,'Earth curves'!$E$2:$E$46,1),1))))+(W12-INDEX('Earth curves'!$E$2:$E$46,MAX(1,MIN(44,IFERROR(MATCH(W12,'Earth curves'!$E$2:$E$46,1),1)))))*(INDEX('Earth curves'!$G$2:$G$46,MAX(1,MIN(44,IFERROR(MATCH(W12,'Earth curves'!$E$2:$E$46,1),1)))+1)-INDEX('Earth curves'!$G$2:$G$46,MAX(1,MIN(44,IFERROR(MATCH(W12,'Earth curves'!$E$2:$E$46,1),1)))))/(INDEX('Earth curves'!$E$2:$E$46,MAX(1,MIN(44,IFERROR(MATCH(W12,'Earth curves'!$E$2:$E$46,1),1)))+1)-INDEX('Earth curves'!$E$2:$E$46,MAX(1,MIN(44,IFERROR(MATCH(W12,'Earth curves'!$E$2:$E$46,1),1)))))) | Z12: =(MIN(X12/Config!$B$9,1)+MIN(Y12/Config!$B$10,1))/2 | AA12: =ROUND(MIN(22,MAX(3,X12*W12/Z12)),1) | AC12: =IF(AB12="",AA12,AB12) | AD12: =ROUND(MIN(Config!$B$10,MAX(1,Y12*W12/Z12)),1) | AF12: =IF(AE12="",AD12,AE12) | AG12: =(V12-Config!$B$7)/(Config!$B$8-Config!$B$7) | AH12: =(MIN(AC12/Config!$B$9,1)+MIN(AF12/Config!$B$10,1))/2 | AI12: =ROUND((AG12*AH12*G12)^(1/3),3) | AJ12: 0.903 | AK12: =AI12-AJ12 | AL12: =AK12-AVERAGE($AK$2:$AK$173) | AM12: =IF(ABS(AL12)>Config!$B$11,"REVIEW","") | AN12: =RANK(AI12,$AI$2:$AI$173) | AO12: =RANK(AJ12,$AJ$2:$AJ$173) | AP12: 12
A13: Astye | B13: New Ayre | C13: resource | D13: 29556 | E13: =D13*Config!$B$4 | F13: =LN(MAX(60,E13)) | G13: =MEDIAN(0,(F13-LN(Config!$B$5))/(LN(Config!$B$6)-LN(Config!$B$5)),1) | H13: =MOD((Config!$B$2+$AP13*7919)*9301+49297,233280)/233280 | I13: =MOD((Config!$B$2+$AP13*104729)*4096+150889,714025)/714025 | J13: =MOD((Config!$B$2*31+$AP13*15485863)*1366+150889,714025)/714025 | K13: 0.009235 | L13: 0.071316 | M13: =COUNTIF(Siblings!$A$2:$A$84,B13) | N13: =1+INT(J13*M13) | O13: =IF(K13<>"",K13,IFERROR(INDEX(Siblings!$D$2:$D$84,MATCH(B13&"|"&N13,Siblings!$F$2:$F$84,0)),0)) | P13: =IF(L13<>"",L13,IFERROR(INDEX(Siblings!$E$2:$E$84,MATCH(B13&"|"&N13,Siblings!$F$2:$F$84,0)),0)) | Q13: =(INDEX('Earth curves'!$B$2:$B$46,MAX(1,MIN(44,IFERROR(MATCH(F13,'Earth curves'!$A$2:$A$46,1),1))))+(F13-INDEX('Earth curves'!$A$2:$A$46,MAX(1,MIN(44,IFERROR(MATCH(F13,'Earth curves'!$A$2:$A$46,1),1)))))*(INDEX('Earth curves'!$B$2:$B$46,MAX(1,MIN(44,IFERROR(MATCH(F13,'Earth curves'!$A$2:$A$46,1),1)))+1)-INDEX('Earth curves'!$B$2:$B$46,MAX(1,MIN(44,IFERROR(MATCH(F13,'Earth curves'!$A$2:$A$46,1),1)))))/(INDEX('Earth curves'!$A$2:$A$46,MAX(1,MIN(44,IFERROR(MATCH(F13,'Earth curves'!$A$2:$A$46,1),1)))+1)-INDEX('Earth curves'!$A$2:$A$46,MAX(1,MIN(44,IFERROR(MATCH(F13,'Earth curves'!$A$2:$A$46,1),1)))))) | R13: =(INDEX('Earth curves'!$C$2:$C$46,MAX(1,MIN(44,IFERROR(MATCH(F13,'Earth curves'!$A$2:$A$46,1),1))))+(F13-INDEX('Earth curves'!$A$2:$A$46,MAX(1,MIN(44,IFERROR(MATCH(F13,'Earth curves'!$A$2:$A$46,1),1)))))*(INDEX('Earth curves'!$C$2:$C$46,MAX(1,MIN(44,IFERROR(MATCH(F13,'Earth curves'!$A$2:$A$46,1),1)))+1)-INDEX('Earth curves'!$C$2:$C$46,MAX(1,MIN(44,IFERROR(MATCH(F13,'Earth curves'!$A$2:$A$46,1),1)))))/(INDEX('Earth curves'!$A$2:$A$46,MAX(1,MIN(44,IFERROR(MATCH(F13,'Earth curves'!$A$2:$A$46,1),1)))+1)-INDEX('Earth curves'!$A$2:$A$46,MAX(1,MIN(44,IFERROR(MATCH(F13,'Earth curves'!$A$2:$A$46,1),1)))))) | S13: =MEDIAN(0.307692,Q13+MEDIAN(-0.350583,O13+NORMSINV(H13)*0.064828*Config!$B$3,0.120277),0.993846) | T13: =ROUND(Config!$B$7+(Config!$B$8-Config!$B$7)*S13,1) | V13: =IF(U13="",T13,U13) | W13: =MEDIAN(0.05,R13+MEDIAN(-0.302219,P13+NORMSINV(I13)*0.089531*Config!$B$3,0.274961),0.999) | X13: =(INDEX('Earth curves'!$F$2:$F$46,MAX(1,MIN(44,IFERROR(MATCH(W13,'Earth curves'!$E$2:$E$46,1),1))))+(W13-INDEX('Earth curves'!$E$2:$E$46,MAX(1,MIN(44,IFERROR(MATCH(W13,'Earth curves'!$E$2:$E$46,1),1)))))*(INDEX('Earth curves'!$F$2:$F$46,MAX(1,MIN(44,IFERROR(MATCH(W13,'Earth curves'!$E$2:$E$46,1),1)))+1)-INDEX('Earth curves'!$F$2:$F$46,MAX(1,MIN(44,IFERROR(MATCH(W13,'Earth curves'!$E$2:$E$46,1),1)))))/(INDEX('Earth curves'!$E$2:$E$46,MAX(1,MIN(44,IFERROR(MATCH(W13,'Earth curves'!$E$2:$E$46,1),1)))+1)-INDEX('Earth curves'!$E$2:$E$46,MAX(1,MIN(44,IFERROR(MATCH(W13,'Earth curves'!$E$2:$E$46,1),1)))))) | Y13: =(INDEX('Earth curves'!$G$2:$G$46,MAX(1,MIN(44,IFERROR(MATCH(W13,'Earth curves'!$E$2:$E$46,1),1))))+(W13-INDEX('Earth curves'!$E$2:$E$46,MAX(1,MIN(44,IFERROR(MATCH(W13,'Earth curves'!$E$2:$E$46,1),1)))))*(INDEX('Earth curves'!$G$2:$G$46,MAX(1,MIN(44,IFERROR(MATCH(W13,'Earth curves'!$E$2:$E$46,1),1)))+1)-INDEX('Earth curves'!$G$2:$G$46,MAX(1,MIN(44,IFERROR(MATCH(W13,'Earth curves'!$E$2:$E$46,1),1)))))/(INDEX('Earth curves'!$E$2:$E$46,MAX(1,MIN(44,IFERROR(MATCH(W13,'Earth curves'!$E$2:$E$46,1),1)))+1)-INDEX('Earth curves'!$E$2:$E$46,MAX(1,MIN(44,IFERROR(MATCH(W13,'Earth curves'!$E$2:$E$46,1),1)))))) | Z13: =(MIN(X13/Config!$B$9,1)+MIN(Y13/Config!$B$10,1))/2 | AA13: =ROUND(MIN(22,MAX(3,X13*W13/Z13)),1) | AC13: =IF(AB13="",AA13,AB13) | AD13: =ROUND(MIN(Config!$B$10,MAX(1,Y13*W13/Z13)),1) | AF13: =IF(AE13="",AD13,AE13) | AG13: =(V13-Config!$B$7)/(Config!$B$8-Config!$B$7) | AH13: =(MIN(AC13/Config!$B$9,1)+MIN(AF13/Config!$B$10,1))/2 | AI13: =ROUND((AG13*AH13*G13)^(1/3),3) | AJ13: 0.751 | AK13: =AI13-AJ13 | AL13: =AK13-AVERAGE($AK$2:$AK$173) | AM13: =IF(ABS(AL13)>Config!$B$11,"REVIEW","") | AN13: =RANK(AI13,$AI$2:$AI$173) | AO13: =RANK(AJ13,$AJ$2:$AJ$173) | AP13: 13
A14: Baluyde | B14: Quia | C14: — | D14: 75238 | E14: =D14*Config!$B$4 | F14: =LN(MAX(60,E14)) | G14: =MEDIAN(0,(F14-LN(Config!$B$5))/(LN(Config!$B$6)-LN(Config!$B$5)),1) | H14: =MOD((Config!$B$2+$AP14*7919)*9301+49297,233280)/233280 | I14: =MOD((Config!$B$2+$AP14*104729)*4096+150889,714025)/714025 | J14: =MOD((Config!$B$2*31+$AP14*15485863)*1366+150889,714025)/714025 | M14: =COUNTIF(Siblings!$A$2:$A$84,B14) | N14: =1+INT(J14*M14) | O14: =IF(K14<>"",K14,IFERROR(INDEX(Siblings!$D$2:$D$84,MATCH(B14&"|"&N14,Siblings!$F$2:$F$84,0)),0)) | P14: =IF(L14<>"",L14,IFERROR(INDEX(Siblings!$E$2:$E$84,MATCH(B14&"|"&N14,Siblings!$F$2:$F$84,0)),0)) | Q14: =(INDEX('Earth curves'!$B$2:$B$46,MAX(1,MIN(44,IFERROR(MATCH(F14,'Earth curves'!$A$2:$A$46,1),1))))+(F14-INDEX('Earth curves'!$A$2:$A$46,MAX(1,MIN(44,IFERROR(MATCH(F14,'Earth curves'!$A$2:$A$46,1),1)))))*(INDEX('Earth curves'!$B$2:$B$46,MAX(1,MIN(44,IFERROR(MATCH(F14,'Earth curves'!$A$2:$A$46,1),1)))+1)-INDEX('Earth curves'!$B$2:$B$46,MAX(1,MIN(44,IFERROR(MATCH(F14,'Earth curves'!$A$2:$A$46,1),1)))))/(INDEX('Earth curves'!$A$2:$A$46,MAX(1,MIN(44,IFERROR(MATCH(F14,'Earth curves'!$A$2:$A$46,1),1)))+1)-INDEX('Earth curves'!$A$2:$A$46,MAX(1,MIN(44,IFERROR(MATCH(F14,'Earth curves'!$A$2:$A$46,1),1)))))) | R14: =(INDEX('Earth curves'!$C$2:$C$46,MAX(1,MIN(44,IFERROR(MATCH(F14,'Earth curves'!$A$2:$A$46,1),1))))+(F14-INDEX('Earth curves'!$A$2:$A$46,MAX(1,MIN(44,IFERROR(MATCH(F14,'Earth curves'!$A$2:$A$46,1),1)))))*(INDEX('Earth curves'!$C$2:$C$46,MAX(1,MIN(44,IFERROR(MATCH(F14,'Earth curves'!$A$2:$A$46,1),1)))+1)-INDEX('Earth curves'!$C$2:$C$46,MAX(1,MIN(44,IFERROR(MATCH(F14,'Earth curves'!$A$2:$A$46,1),1)))))/(INDEX('Earth curves'!$A$2:$A$46,MAX(1,MIN(44,IFERROR(MATCH(F14,'Earth curves'!$A$2:$A$46,1),1)))+1)-INDEX('Earth curves'!$A$2:$A$46,MAX(1,MIN(44,IFERROR(MATCH(F14,'Earth curves'!$A$2:$A$46,1),1)))))) | S14: =MEDIAN(0.307692,Q14+MEDIAN(-0.350583,O14+NORMSINV(H14)*0.064828*Config!$B$3,0.120277),0.993846) | T14: =ROUND(Config!$B$7+(Config!$B$8-Config!$B$7)*S14,1) | V14: =IF(U14="",T14,U14) | W14: =MEDIAN(0.05,R14+MEDIAN(-0.302219,P14+NORMSINV(I14)*0.089531*Config!$B$3,0.274961),0.999) | X14: =(INDEX('Earth curves'!$F$2:$F$46,MAX(1,MIN(44,IFERROR(MATCH(W14,'Earth curves'!$E$2:$E$46,1),1))))+(W14-INDEX('Earth curves'!$E$2:$E$46,MAX(1,MIN(44,IFERROR(MATCH(W14,'Earth curves'!$E$2:$E$46,1),1)))))*(INDEX('Earth curves'!$F$2:$F$46,MAX(1,MIN(44,IFERROR(MATCH(W14,'Earth curves'!$E$2:$E$46,1),1)))+1)-INDEX('Earth curves'!$F$2:$F$46,MAX(1,MIN(44,IFERROR(MATCH(W14,'Earth curves'!$E$2:$E$46,1),1)))))/(INDEX('Earth curves'!$E$2:$E$46,MAX(1,MIN(44,IFERROR(MATCH(W14,'Earth curves'!$E$2:$E$46,1),1)))+1)-INDEX('Earth curves'!$E$2:$E$46,MAX(1,MIN(44,IFERROR(MATCH(W14,'Earth curves'!$E$2:$E$46,1),1)))))) | Y14: =(INDEX('Earth curves'!$G$2:$G$46,MAX(1,MIN(44,IFERROR(MATCH(W14,'Earth curves'!$E$2:$E$46,1),1))))+(W14-INDEX('Earth curves'!$E$2:$E$46,MAX(1,MIN(44,IFERROR(MATCH(W14,'Earth curves'!$E$2:$E$46,1),1)))))*(INDEX('Earth curves'!$G$2:$G$46,MAX(1,MIN(44,IFERROR(MATCH(W14,'Earth curves'!$E$2:$E$46,1),1)))+1)-INDEX('Earth curves'!$G$2:$G$46,MAX(1,MIN(44,IFERROR(MATCH(W14,'Earth curves'!$E$2:$E$46,1),1)))))/(INDEX('Earth curves'!$E$2:$E$46,MAX(1,MIN(44,IFERROR(MATCH(W14,'Earth curves'!$E$2:$E$46,1),1)))+1)-INDEX('Earth curves'!$E$2:$E$46,MAX(1,MIN(44,IFERROR(MATCH(W14,'Earth curves'!$E$2:$E$46,1),1)))))) | Z14: =(MIN(X14/Config!$B$9,1)+MIN(Y14/Config!$B$10,1))/2 | AA14: =ROUND(MIN(22,MAX(3,X14*W14/Z14)),1) | AC14: =IF(AB14="",AA14,AB14) | AD14: =ROUND(MIN(Config!$B$10,MAX(1,Y14*W14/Z14)),1) | AF14: =IF(AE14="",AD14,AE14) | AG14: =(V14-Config!$B$7)/(Config!$B$8-Config!$B$7) | AH14: =(MIN(AC14/Config!$B$9,1)+MIN(AF14/Config!$B$10,1))/2 | AI14: =ROUND((AG14*AH14*G14)^(1/3),3) | AJ14: 0.705 | AK14: =AI14-AJ14 | AL14: =AK14-AVERAGE($AK$2:$AK$173) | AM14: =IF(ABS(AL14)>Config!$B$11,"REVIEW","") | AN14: =RANK(AI14,$AI$2:$AI$173) | AO14: =RANK(AJ14,$AJ$2:$AJ$173) | AP14: 14
A15: Byllu | B15: Mahea | C15: — | D15: 11079 | E15: =D15*Config!$B$4 | F15: =LN(MAX(60,E15)) | G15: =MEDIAN(0,(F15-LN(Config!$B$5))/(LN(Config!$B$6)-LN(Config!$B$5)),1) | H15: =MOD((Config!$B$2+$AP15*7919)*9301+49297,233280)/233280 | I15: =MOD((Config!$B$2+$AP15*104729)*4096+150889,714025)/714025 | J15: =MOD((Config!$B$2*31+$AP15*15485863)*1366+150889,714025)/714025 | M15: =COUNTIF(Siblings!$A$2:$A$84,B15) | N15: =1+INT(J15*M15) | O15: =IF(K15<>"",K15,IFERROR(INDEX(Siblings!$D$2:$D$84,MATCH(B15&"|"&N15,Siblings!$F$2:$F$84,0)),0)) | P15: =IF(L15<>"",L15,IFERROR(INDEX(Siblings!$E$2:$E$84,MATCH(B15&"|"&N15,Siblings!$F$2:$F$84,0)),0)) | Q15: =(INDEX('Earth curves'!$B$2:$B$46,MAX(1,MIN(44,IFERROR(MATCH(F15,'Earth curves'!$A$2:$A$46,1),1))))+(F15-INDEX('Earth curves'!$A$2:$A$46,MAX(1,MIN(44,IFERROR(MATCH(F15,'Earth curves'!$A$2:$A$46,1),1)))))*(INDEX('Earth curves'!$B$2:$B$46,MAX(1,MIN(44,IFERROR(MATCH(F15,'Earth curves'!$A$2:$A$46,1),1)))+1)-INDEX('Earth curves'!$B$2:$B$46,MAX(1,MIN(44,IFERROR(MATCH(F15,'Earth curves'!$A$2:$A$46,1),1)))))/(INDEX('Earth curves'!$A$2:$A$46,MAX(1,MIN(44,IFERROR(MATCH(F15,'Earth curves'!$A$2:$A$46,1),1)))+1)-INDEX('Earth curves'!$A$2:$A$46,MAX(1,MIN(44,IFERROR(MATCH(F15,'Earth curves'!$A$2:$A$46,1),1)))))) | R15: =(INDEX('Earth curves'!$C$2:$C$46,MAX(1,MIN(44,IFERROR(MATCH(F15,'Earth curves'!$A$2:$A$46,1),1))))+(F15-INDEX('Earth curves'!$A$2:$A$46,MAX(1,MIN(44,IFERROR(MATCH(F15,'Earth curves'!$A$2:$A$46,1),1)))))*(INDEX('Earth curves'!$C$2:$C$46,MAX(1,MIN(44,IFERROR(MATCH(F15,'Earth curves'!$A$2:$A$46,1),1)))+1)-INDEX('Earth curves'!$C$2:$C$46,MAX(1,MIN(44,IFERROR(MATCH(F15,'Earth curves'!$A$2:$A$46,1),1)))))/(INDEX('Earth curves'!$A$2:$A$46,MAX(1,MIN(44,IFERROR(MATCH(F15,'Earth curves'!$A$2:$A$46,1),1)))+1)-INDEX('Earth curves'!$A$2:$A$46,MAX(1,MIN(44,IFERROR(MATCH(F15,'Earth curves'!$A$2:$A$46,1),1)))))) | S15: =MEDIAN(0.307692,Q15+MEDIAN(-0.350583,O15+NORMSINV(H15)*0.064828*Config!$B$3,0.120277),0.993846) | T15: =ROUND(Config!$B$7+(Config!$B$8-Config!$B$7)*S15,1) | V15: =IF(U15="",T15,U15) | W15: =MEDIAN(0.05,R15+MEDIAN(-0.302219,P15+NORMSINV(I15)*0.089531*Config!$B$3,0.274961),0.999) | X15: =(INDEX('Earth curves'!$F$2:$F$46,MAX(1,MIN(44,IFERROR(MATCH(W15,'Earth curves'!$E$2:$E$46,1),1))))+(W15-INDEX('Earth curves'!$E$2:$E$46,MAX(1,MIN(44,IFERROR(MATCH(W15,'Earth curves'!$E$2:$E$46,1),1)))))*(INDEX('Earth curves'!$F$2:$F$46,MAX(1,MIN(44,IFERROR(MATCH(W15,'Earth curves'!$E$2:$E$46,1),1)))+1)-INDEX('Earth curves'!$F$2:$F$46,MAX(1,MIN(44,IFERROR(MATCH(W15,'Earth curves'!$E$2:$E$46,1),1)))))/(INDEX('Earth curves'!$E$2:$E$46,MAX(1,MIN(44,IFERROR(MATCH(W15,'Earth curves'!$E$2:$E$46,1),1)))+1)-INDEX('Earth curves'!$E$2:$E$46,MAX(1,MIN(44,IFERROR(MATCH(W15,'Earth curves'!$E$2:$E$46,1),1)))))) | Y15: =(INDEX('Earth curves'!$G$2:$G$46,MAX(1,MIN(44,IFERROR(MATCH(W15,'Earth curves'!$E$2:$E$46,1),1))))+(W15-INDEX('Earth curves'!$E$2:$E$46,MAX(1,MIN(44,IFERROR(MATCH(W15,'Earth curves'!$E$2:$E$46,1),1)))))*(INDEX('Earth curves'!$G$2:$G$46,MAX(1,MIN(44,IFERROR(MATCH(W15,'Earth curves'!$E$2:$E$46,1),1)))+1)-INDEX('Earth curves'!$G$2:$G$46,MAX(1,MIN(44,IFERROR(MATCH(W15,'Earth curves'!$E$2:$E$46,1),1)))))/(INDEX('Earth curves'!$E$2:$E$46,MAX(1,MIN(44,IFERROR(MATCH(W15,'Earth curves'!$E$2:$E$46,1),1)))+1)-INDEX('Earth curves'!$E$2:$E$46,MAX(1,MIN(44,IFERROR(MATCH(W15,'Earth curves'!$E$2:$E$46,1),1)))))) | Z15: =(MIN(X15/Config!$B$9,1)+MIN(Y15/Config!$B$10,1))/2 | AA15: =ROUND(MIN(22,MAX(3,X15*W15/Z15)),1) | AC15: =IF(AB15="",AA15,AB15) | AD15: =ROUND(MIN(Config!$B$10,MAX(1,Y15*W15/Z15)),1) | AF15: =IF(AE15="",AD15,AE15) | AG15: =(V15-Config!$B$7)/(Config!$B$8-Config!$B$7) | AH15: =(MIN(AC15/Config!$B$9,1)+MIN(AF15/Config!$B$10,1))/2 | AI15: =ROUND((AG15*AH15*G15)^(1/3),3) | AJ15: 0.687 | AK15: =AI15-AJ15 | AL15: =AK15-AVERAGE($AK$2:$AK$173) | AM15: =IF(ABS(AL15)>Config!$B$11,"REVIEW","") | AN15: =RANK(AI15,$AI$2:$AI$173) | AO15: =RANK(AJ15,$AJ$2:$AJ$173) | AP15: 15
